data/output-ground-truth/SONG.txt
PASSIVE BUY 780.00 @ 930.70
PASSIVE SELL 1380.00 @ 931.30
PASSIVE BUY 740.00 @ 930.59
PASSIVE BUY 2860.00 @ 930.68
PASSIVE BUY 2900.00 @ 930.72
PASSIVE BUY 1780.00 @ 930.74
PASSIVE SELL 1460.00 @ 931.38
PASSIVE SELL 1420.00 @ 931.16
PASSIVE SELL 2260.00 @ 931.00
PASSIVE BUY 980.00 @ 930.75
PASSIVE SELL 1900.00 @ 931.05
PASSIVE SELL 2020.00 @ 931.01
PASSIVE SELL 1140.00 @ 930.96
CANCEL SELL 1460.00 @ 931.38
PASSIVE BUY 1540.00 @ 930.73
CANCEL BUY 780.00 @ 930.70
CANCEL BUY 740.00 @ 930.59
CANCEL BUY 2860.00 @ 930.68
CANCEL BUY 2900.00 @ 930.72
CANCEL BUY 1780.00 @ 930.74
CANCEL BUY 980.00 @ 930.75
CANCEL BUY 1540.00 @ 930.73
PASSIVE BUY 2740.00 @ 930.77
PASSIVE SELL 2140.00 @ 930.87
CANCEL SELL 1380.00 @ 931.30
PASSIVE SELL 860.00 @ 930.94
CANCEL SELL 1420.00 @ 931.16
PASSIVE BUY 1660.00 @ 930.71
AGGRESSIVE SELL 1580.00 @ 930.77
PASSIVE SELL 2220.00 @ 930.93
CANCEL SELL 1900.00 @ 931.05
PASSIVE SELL 1020.00 @ 930.79
CANCEL SELL 2020.00 @ 931.01
PASSIVE SELL 1460.00 @ 930.87
PASSIVE BUY 2900.00 @ 930.69
AGGRESSIVE BUY 2140.00 @ 930.80
AGGRESSIVE BUY 1740.00 @ 930.87
AGGRESSIVE SELL 1060.00 @ 930.80
AGGRESSIVE SELL 1340.00 @ 930.75
PASSIVE BUY 1860.00 @ 930.63
AGGRESSIVE BUY 2500.00 @ 930.87
PASSIVE BUY 1260.00 @ 930.86
PASSIVE SELL 1500.00 @ 930.90
PASSIVE BUY 1580.00 @ 930.78
PASSIVE SELL 660.00 @ 931.03
AGGRESSIVE BUY 2460.00 @ 930.93
PASSIVE BUY 1740.00 @ 930.81
CANCEL BUY 1660.00 @ 930.71
CANCEL BUY 2900.00 @ 930.69
CANCEL BUY 1860.00 @ 930.63
CANCEL BUY 520.00 @ 930.87
CANCEL BUY 1260.00 @ 930.86
CANCEL BUY 1580.00 @ 930.78
CANCEL BUY 1740.00 @ 930.81
AGGRESSIVE BUY 2420.00 @ 930.96
PASSIVE SELL 380.00 @ 930.82
PASSIVE SELL 1700.00 @ 930.66
AGGRESSIVE BUY 1620.00 @ 930.66
PASSIVE SELL 1940.00 @ 930.67
PASSIVE SELL 1460.00 @ 930.58
CANCEL SELL 660.00 @ 931.03
AGGRESSIVE BUY 780.00 @ 930.58
PASSIVE SELL 420.00 @ 930.52
CANCEL SELL 2260.00 @ 931.00
AGGRESSIVE BUY 1300.00 @ 930.67
AGGRESSIVE BUY 1980.00 @ 930.82
PASSIVE SELL 460.00 @ 930.85
AGGRESSIVE BUY 940.00 @ 930.88
PASSIVE BUY 1780.00 @ 930.84
AGGRESSIVE BUY 2380.00 @ 931.02
PASSIVE SELL 500.00 @ 931.15
PASSIVE SELL 2140.00 @ 931.21
PASSIVE BUY 1020.00 @ 931.09
PASSIVE SELL 1100.00 @ 931.21
PASSIVE SELL 380.00 @ 931.24
AGGRESSIVE SELL 940.00 @ 931.09
PASSIVE SELL 2220.00 @ 931.12
AGGRESSIVE SELL 580.00 @ 931.02
AGGRESSIVE SELL 1340.00 @ 931.00
AGGRESSIVE BUY 1460.00 @ 931.03
AGGRESSIVE SELL 1820.00 @ 930.97
PASSIVE SELL 940.00 @ 930.92
PASSIVE SELL 1020.00 @ 931.04
CANCEL SELL 380.00 @ 931.24
AGGRESSIVE BUY 1060.00 @ 930.97
PASSIVE SELL 500.00 @ 931.04
AGGRESSIVE BUY 2340.00 @ 931.01
PASSIVE SELL 1060.00 @ 931.05
PASSIVE SELL 1500.00 @ 931.16
AGGRESSIVE BUY 2020.00 @ 931.05
PASSIVE SELL 860.00 @ 931.05
AGGRESSIVE SELL 1940.00 @ 930.91
PASSIVE SELL 1420.00 @ 931.02
CANCEL SELL -2140.00 @ 931.21
CANCEL SELL 1100.00 @ 931.21
AGGRESSIVE BUY 1100.00 @ 930.91
AGGRESSIVE BUY 2140.00 @ 931.05
PASSIVE SELL 1860.00 @ 931.15
PASSIVE BUY 860.00 @ 930.99
AGGRESSIVE SELL 1660.00 @ 930.99
PASSIVE BUY 900.00 @ 930.81
PASSIVE SELL 1420.00 @ 930.93
PASSIVE BUY 1740.00 @ 930.87
AGGRESSIVE SELL 1100.00 @ 930.88
AGGRESSIVE SELL 460.00 @ 930.87
PASSIVE BUY 1260.00 @ 930.86
PASSIVE BUY 1980.00 @ 930.78
PASSIVE BUY 2860.00 @ 930.83
PASSIVE SELL 1460.00 @ 930.90
CANCEL SELL 1500.00 @ 931.16
AGGRESSIVE SELL 1500.00 @ 930.86
PASSIVE BUY 1580.00 @ 930.80
PASSIVE BUY 1260.00 @ 930.77
CANCEL BUY 1780.00 @ 930.84
CANCEL BUY 900.00 @ 930.81
CANCEL BUY 1160.00 @ 930.86
CANCEL BUY 1980.00 @ 930.78
CANCEL BUY 2860.00 @ 930.83
CANCEL BUY 1580.00 @ 930.80
CANCEL BUY 1260.00 @ 930.77
PASSIVE SELL 1420.00 @ 930.93
PASSIVE SELL 1780.00 @ 930.95
CANCEL SELL -500.00 @ 931.15
CANCEL SELL 1860.00 @ 931.15
PASSIVE SELL 1100.00 @ 930.76
CANCEL SELL 2220.00 @ 931.12
AGGRESSIVE BUY 2340.00 @ 930.76
PASSIVE BUY 2660.00 @ 930.76
PASSIVE BUY 2740.00 @ 930.76
PASSIVE BUY 1500.00 @ 930.87
PASSIVE BUY 1340.00 @ 930.83
AGGRESSIVE SELL 1300.00 @ 930.87
PASSIVE SELL 780.00 @ 930.90
PASSIVE SELL 860.00 @ 930.99
AGGRESSIVE SELL 1500.00 @ 930.83
PASSIVE BUY 1500.00 @ 930.74
PASSIVE SELL 2220.00 @ 930.89
PASSIVE SELL 820.00 @ 930.99
AGGRESSIVE SELL 1380.00 @ 930.76
PASSIVE SELL 1740.00 @ 930.83
CANCEL SELL 700.00 @ 931.05
PASSIVE SELL 1940.00 @ 930.92
CANCEL SELL -800.00 @ 930.99
CANCEL SELL -860.00 @ 930.99
CANCEL SELL 820.00 @ 930.99
PASSIVE BUY 1820.00 @ 930.65
PASSIVE SELL 1540.00 @ 930.94
CANCEL SELL 1780.00 @ 930.95
PASSIVE BUY 1260.00 @ 930.66
PASSIVE SELL 940.00 @ 930.82
CANCEL SELL 1540.00 @ 930.94
AGGRESSIVE BUY 1900.00 @ 930.83
AGGRESSIVE SELL 2180.00 @ 930.76
PASSIVE BUY 1460.00 @ 930.71
PASSIVE SELL 580.00 @ 930.80
PASSIVE BUY 2860.00 @ 930.66
AGGRESSIVE BUY 1820.00 @ 930.89
PASSIVE SELL 940.00 @ 930.77
AGGRESSIVE BUY 2060.00 @ 930.86
AGGRESSIVE BUY 1420.00 @ 930.89
PASSIVE BUY 1020.00 @ 930.81
CANCEL BUY -380.00 @ 930.76
CANCEL BUY 2740.00 @ 930.76
CANCEL BUY 1500.00 @ 930.74
CANCEL BUY 1820.00 @ 930.65
CANCEL BUY -1260.00 @ 930.66
CANCEL BUY 1460.00 @ 930.71
CANCEL BUY 2860.00 @ 930.66
CANCEL BUY 1120.00 @ 930.86
CANCEL BUY 1020.00 @ 930.81
PASSIVE BUY 860.00 @ 930.73
PASSIVE SELL 1060.00 @ 930.93
PASSIVE SELL 1300.00 @ 930.94
PASSIVE BUY 1300.00 @ 930.74
PASSIVE BUY 2500.00 @ 930.66
PASSIVE SELL 1340.00 @ 931.03
PASSIVE BUY 1980.00 @ 930.70
PASSIVE BUY 900.00 @ 930.71
PASSIVE SELL 660.00 @ 930.77
CANCEL SELL 1340.00 @ 931.03
AGGRESSIVE BUY 860.00 @ 930.89
PASSIVE BUY 780.00 @ 930.66
AGGRESSIVE BUY 2020.00 @ 930.90
PASSIVE BUY 2940.00 @ 930.63
PASSIVE SELL 500.00 @ 930.87
AGGRESSIVE SELL 1100.00 @ 930.74
PASSIVE SELL 2260.00 @ 930.93
PASSIVE SELL 1900.00 @ 930.90
PASSIVE BUY 2820.00 @ 930.86
CANCEL BUY 860.00 @ 930.73
CANCEL BUY 200.00 @ 930.74
CANCEL BUY -2500.00 @ 930.66
CANCEL BUY 1980.00 @ 930.70
CANCEL BUY 900.00 @ 930.71
CANCEL BUY 780.00 @ 930.66
CANCEL BUY 2940.00 @ 930.63
CANCEL BUY 2820.00 @ 930.86
PASSIVE BUY 1780.00 @ 930.74
PASSIVE SELL 860.00 @ 930.86
PASSIVE BUY 2500.00 @ 930.69
PASSIVE BUY 900.00 @ 930.70
PASSIVE SELL 380.00 @ 930.75
CANCEL SELL 1300.00 @ 930.94
AGGRESSIVE BUY 2780.00 @ 930.90
PASSIVE SELL 1940.00 @ 930.80
PASSIVE SELL 380.00 @ 930.76
AGGRESSIVE SELL 700.00 @ 930.74
PASSIVE SELL 2060.00 @ 930.84
AGGRESSIVE SELL 2260.00 @ 930.69
AGGRESSIVE SELL 2020.00 @ 930.69
AGGRESSIVE SELL 2180.00 @ 930.66
CANCEL SELL -1420.00 @ 930.93
CANCEL SELL -1420.00 @ 930.93
CANCEL SELL -1060.00 @ 930.93
CANCEL SELL 2260.00 @ 930.93
AGGRESSIVE BUY 1660.00 @ 930.66
AGGRESSIVE BUY 1660.00 @ 930.73
PASSIVE SELL 1780.00 @ 930.80
PASSIVE SELL 1420.00 @ 930.78
PASSIVE SELL 740.00 @ 930.85
CANCEL SELL 1940.00 @ 930.92
PASSIVE BUY 1100.00 @ 930.72
AGGRESSIVE SELL 580.00 @ 930.73
PASSIVE BUY 1180.00 @ 930.68
AGGRESSIVE BUY 1540.00 @ 930.78
PASSIVE SELL 1220.00 @ 930.91
PASSIVE SELL 1420.00 @ 930.74
CANCEL SELL 1220.00 @ 930.91
AGGRESSIVE SELL 1620.00 @ 930.72
AGGRESSIVE BUY 820.00 @ 930.74
PASSIVE BUY 2140.00 @ 930.60
PASSIVE SELL 1860.00 @ 930.82
CANCEL SELL 1220.00 @ 930.90
AGGRESSIVE SELL 1140.00 @ 930.68
PASSIVE BUY 2340.00 @ 930.61
PASSIVE SELL 1540.00 @ 930.77
CANCEL SELL 740.00 @ 930.85
AGGRESSIVE SELL 1460.00 @ 930.62
CANCEL SELL 2060.00 @ 930.84
AGGRESSIVE SELL 1580.00 @ 930.61
AGGRESSIVE BUY 740.00 @ 930.62
AGGRESSIVE SELL 940.00 @ 930.60
PASSIVE BUY 2820.00 @ 930.55
PASSIVE BUY 940.00 @ 930.55
AGGRESSIVE BUY 1140.00 @ 930.69
PASSIVE BUY 780.00 @ 930.73
AGGRESSIVE SELL 2100.00 @ 930.62
PASSIVE SELL 2020.00 @ 930.69
CANCEL SELL 1860.00 @ 930.82
AGGRESSIVE SELL 1460.00 @ 930.60
AGGRESSIVE SELL 1700.00 @ 930.55
AGGRESSIVE SELL 780.00 @ 930.55
PASSIVE BUY 2820.00 @ 930.56
PASSIVE SELL 2020.00 @ 930.61
CANCEL SELL -1940.00 @ 930.80
CANCEL SELL 1780.00 @ 930.80
AGGRESSIVE SELL 620.00 @ 930.56
PASSIVE BUY 2220.00 @ 930.53
PASSIVE BUY 2540.00 @ 930.60
AGGRESSIVE BUY 2060.00 @ 930.62
PASSIVE SELL 1900.00 @ 930.74
PASSIVE BUY 780.00 @ 930.52
PASSIVE BUY 1340.00 @ 930.58
AGGRESSIVE SELL 1300.00 @ 930.60
PASSIVE SELL 1020.00 @ 930.74
PASSIVE BUY 1660.00 @ 930.56
PASSIVE SELL 1140.00 @ 930.65
AGGRESSIVE SELL 1700.00 @ 930.59
CANCEL SELL 260.00 @ 930.78
