data/output-ground-truth/TAK.txt
PASSIVE BUY 860.00 @ 90.76
PASSIVE BUY 1060.00 @ 90.88
PASSIVE SELL 1700.00 @ 91.29
PASSIVE BUY 2780.00 @ 90.96
PASSIVE BUY 860.00 @ 91.14
PASSIVE BUY 1660.00 @ 91.16
PASSIVE SELL 2140.00 @ 91.31
AGGRESSIVE SELL 1420.00 @ 91.16
PASSIVE SELL 980.00 @ 91.30
AGGRESSIVE BUY 1180.00 @ 91.29
PASSIVE BUY 2260.00 @ 91.19
PASSIVE SELL 1100.00 @ 91.37
AGGRESSIVE SELL 1180.00 @ 91.19
PASSIVE SELL 1100.00 @ 91.37
PASSIVE SELL 2220.00 @ 91.28
PASSIVE BUY 1020.00 @ 91.13
CANCEL BUY 860.00 @ 90.76
CANCEL BUY 1060.00 @ 90.88
CANCEL BUY 2780.00 @ 90.96
CANCEL BUY 860.00 @ 91.14
CANCEL BUY 240.00 @ 91.16
CANCEL BUY 1080.00 @ 91.19
CANCEL BUY 1020.00 @ 91.13
PASSIVE SELL 900.00 @ 91.37
AGGRESSIVE BUY 1700.00 @ 91.28
PASSIVE SELL 620.00 @ 91.38
PASSIVE BUY 1180.00 @ 91.16
PASSIVE BUY 1980.00 @ 91.13
AGGRESSIVE SELL 2260.00 @ 91.13
AGGRESSIVE BUY 2860.00 @ 91.31
PASSIVE BUY 2060.00 @ 91.14
PASSIVE SELL 2180.00 @ 91.16
PASSIVE BUY 2620.00 @ 91.10
AGGRESSIVE SELL 1020.00 @ 91.14
AGGRESSIVE BUY 1500.00 @ 91.16
PASSIVE BUY 780.00 @ 91.15
PASSIVE BUY 1220.00 @ 91.07
AGGRESSIVE BUY 1540.00 @ 91.27
PASSIVE SELL 780.00 @ 91.41
AGGRESSIVE SELL 980.00 @ 91.15
PASSIVE BUY 1540.00 @ 91.11
PASSIVE SELL 1300.00 @ 91.33
PASSIVE SELL 1140.00 @ 91.21
PASSIVE SELL 2300.00 @ 91.26
CANCEL SELL 780.00 @ 91.41
AGGRESSIVE SELL 1260.00 @ 91.14
PASSIVE SELL 1540.00 @ 91.16
CANCEL SELL 620.00 @ 91.38
PASSIVE BUY 2220.00 @ 91.04
PASSIVE SELL 660.00 @ 91.17
CANCEL SELL -1100.00 @ 91.37
CANCEL SELL -1100.00 @ 91.37
CANCEL SELL 900.00 @ 91.37
PASSIVE SELL 1540.00 @ 91.22
CANCEL SELL 1300.00 @ 91.33
PASSIVE BUY 1100.00 @ 91.06
CANCEL BUY 900.00 @ 91.13
CANCEL BUY 440.00 @ 91.14
CANCEL BUY 2620.00 @ 91.10
CANCEL BUY 1220.00 @ 91.07
CANCEL BUY 1540.00 @ 91.11
CANCEL BUY 2220.00 @ 91.04
CANCEL BUY 1100.00 @ 91.06
PASSIVE SELL 1740.00 @ 91.22
PASSIVE SELL 1540.00 @ 91.04
CANCEL SELL 1300.00 @ 91.31
AGGRESSIVE BUY 2940.00 @ 91.16
PASSIVE SELL 1300.00 @ 91.05
AGGRESSIVE BUY 780.00 @ 91.05
AGGRESSIVE BUY 1580.00 @ 91.16
PASSIVE BUY 2500.00 @ 91.16
PASSIVE SELL 1180.00 @ 91.22
PASSIVE BUY 2340.00 @ 91.12
PASSIVE BUY 1180.00 @ 91.04
AGGRESSIVE BUY 2060.00 @ 91.20
AGGRESSIVE SELL 1380.00 @ 91.20
AGGRESSIVE BUY 1220.00 @ 91.22
PASSIVE BUY 2340.00 @ 91.08
PASSIVE SELL 1220.00 @ 91.25
PASSIVE SELL 2260.00 @ 91.33
AGGRESSIVE SELL 2300.00 @ 91.20
PASSIVE SELL 2300.00 @ 91.24
PASSIVE SELL 460.00 @ 91.23
CANCEL SELL 2260.00 @ 91.33
AGGRESSIVE BUY 2860.00 @ 91.22
PASSIVE BUY 820.00 @ 91.21
PASSIVE SELL 2140.00 @ 91.25
AGGRESSIVE SELL 980.00 @ 91.16
PASSIVE BUY 2780.00 @ 91.17
AGGRESSIVE SELL 940.00 @ 91.17
AGGRESSIVE SELL 420.00 @ 91.17
PASSIVE BUY 2100.00 @ 91.11
PASSIVE SELL 1300.00 @ 91.29
PASSIVE BUY 2660.00 @ 91.13
CANCEL BUY -760.00 @ 91.16
CANCEL BUY 2500.00 @ 91.16
CANCEL BUY 2340.00 @ 91.12
CANCEL BUY 1180.00 @ 91.04
CANCEL BUY 2340.00 @ 91.08
CANCEL BUY 1420.00 @ 91.17
CANCEL BUY 2100.00 @ 91.11
CANCEL BUY 2660.00 @ 91.13
AGGRESSIVE BUY 1020.00 @ 91.22
AGGRESSIVE BUY 1620.00 @ 91.22
PASSIVE BUY 2780.00 @ 91.15
PASSIVE SELL 1260.00 @ 91.19
CANCEL SELL 1300.00 @ 91.29
AGGRESSIVE BUY 740.00 @ 91.19
AGGRESSIVE SELL 1340.00 @ 91.15
PASSIVE BUY 1140.00 @ 91.14
AGGRESSIVE BUY 2620.00 @ 91.21
AGGRESSIVE BUY 2700.00 @ 91.24
AGGRESSIVE BUY 2100.00 @ 91.25
AGGRESSIVE BUY 2900.00 @ 91.26
AGGRESSIVE SELL 780.00 @ 91.21
PASSIVE SELL 460.00 @ 91.37
AGGRESSIVE SELL 1380.00 @ 91.18
AGGRESSIVE SELL 2300.00 @ 91.14
AGGRESSIVE BUY 980.00 @ 91.22
PASSIVE SELL 1660.00 @ 91.23
AGGRESSIVE SELL 820.00 @ 91.22
AGGRESSIVE BUY 1380.00 @ 91.23
AGGRESSIVE BUY 1340.00 @ 91.25
AGGRESSIVE SELL 1140.00 @ 91.23
AGGRESSIVE SELL 980.00 @ 91.21
PASSIVE BUY 1140.00 @ 91.05
AGGRESSIVE SELL 380.00 @ 91.07
PASSIVE SELL 780.00 @ 91.08
AGGRESSIVE BUY 1900.00 @ 91.20
AGGRESSIVE BUY 1260.00 @ 91.26
PASSIVE SELL 940.00 @ 91.32
AGGRESSIVE SELL 2140.00 @ 91.09
PASSIVE SELL 740.00 @ 91.11
PASSIVE SELL 420.00 @ 91.16
PASSIVE SELL 2020.00 @ 91.06
CANCEL SELL 460.00 @ 91.37
AGGRESSIVE SELL 1220.00 @ 90.97
CANCEL SELL 940.00 @ 91.32
PASSIVE SELL 2300.00 @ 90.96
CANCEL SELL 1580.00 @ 91.26
PASSIVE SELL 460.00 @ 90.82
CANCEL SELL 420.00 @ 91.16
AGGRESSIVE BUY 2300.00 @ 90.89
PASSIVE SELL 460.00 @ 91.06
AGGRESSIVE SELL 1740.00 @ 90.89
AGGRESSIVE SELL 1380.00 @ 90.86
PASSIVE SELL 2100.00 @ 90.72
CANCEL SELL 740.00 @ 91.11
PASSIVE SELL 1380.00 @ 90.77
CANCEL SELL 1120.00 @ 91.09
AGGRESSIVE BUY 2860.00 @ 90.77
PASSIVE SELL 980.00 @ 90.89
PASSIVE SELL 1700.00 @ 90.86
AGGRESSIVE BUY 900.00 @ 90.79
PASSIVE SELL 2140.00 @ 90.86
AGGRESSIVE BUY 2620.00 @ 90.86
PASSIVE BUY 2140.00 @ 90.70
PASSIVE BUY 2860.00 @ 90.85
PASSIVE SELL 380.00 @ 90.95
AGGRESSIVE BUY 1540.00 @ 90.86
AGGRESSIVE BUY 2140.00 @ 90.95
PASSIVE BUY 2060.00 @ 90.90
PASSIVE SELL 1060.00 @ 90.91
PASSIVE SELL 2100.00 @ 90.91
AGGRESSIVE BUY 1140.00 @ 90.91
AGGRESSIVE BUY 1980.00 @ 90.91
PASSIVE BUY 1060.00 @ 90.84
AGGRESSIVE SELL 1740.00 @ 90.90
AGGRESSIVE SELL 860.00 @ 90.85
PASSIVE SELL 1140.00 @ 90.87
AGGRESSIVE SELL 1340.00 @ 90.85
PASSIVE BUY 1940.00 @ 90.77
PASSIVE BUY 1220.00 @ 90.78
AGGRESSIVE BUY 2460.00 @ 90.96
PASSIVE SELL 540.00 @ 91.03
PASSIVE BUY 2780.00 @ 90.87
CANCEL BUY 280.00 @ 90.79
CANCEL BUY 2140.00 @ 90.70
CANCEL BUY 980.00 @ 90.85
CANCEL BUY 1060.00 @ 90.84
CANCEL BUY 1940.00 @ 90.77
CANCEL BUY 1220.00 @ 90.78
CANCEL BUY 2780.00 @ 90.87
PASSIVE SELL 860.00 @ 90.91
PASSIVE SELL 1460.00 @ 90.99
AGGRESSIVE BUY 1620.00 @ 90.94
PASSIVE SELL 740.00 @ 91.07
PASSIVE SELL 660.00 @ 91.03
AGGRESSIVE BUY 1820.00 @ 90.99
AGGRESSIVE SELL 660.00 @ 90.94
PASSIVE BUY 2380.00 @ 90.98
PASSIVE SELL 1820.00 @ 91.04
AGGRESSIVE SELL 900.00 @ 90.98
PASSIVE SELL 1060.00 @ 91.12
AGGRESSIVE BUY 2060.00 @ 91.03
AGGRESSIVE BUY 900.00 @ 91.04
PASSIVE BUY 1940.00 @ 90.94
PASSIVE BUY 2540.00 @ 90.90
PASSIVE BUY 2660.00 @ 90.97
PASSIVE SELL 1580.00 @ 91.10
PASSIVE SELL 1940.00 @ 91.13
PASSIVE BUY 1060.00 @ 90.89
PASSIVE SELL 1940.00 @ 91.03
CANCEL SELL 1940.00 @ 91.13
AGGRESSIVE BUY 2540.00 @ 91.04
AGGRESSIVE SELL 1820.00 @ 90.97
AGGRESSIVE BUY 2300.00 @ 91.05
PASSIVE BUY 860.00 @ 91.03
PASSIVE BUY 2620.00 @ 91.04
CANCEL BUY -100.00 @ 90.94
CANCEL BUY 1940.00 @ 90.94
CANCEL BUY 2540.00 @ 90.90
CANCEL BUY 2320.00 @ 90.97
CANCEL BUY 1060.00 @ 90.89
CANCEL BUY 1920.00 @ 91.05
CANCEL BUY 860.00 @ 91.03
CANCEL BUY 2620.00 @ 91.04
PASSIVE SELL 1100.00 @ 91.18
PASSIVE BUY 1980.00 @ 90.90
PASSIVE BUY 2540.00 @ 90.98
AGGRESSIVE SELL 1540.00 @ 90.98
PASSIVE BUY 2020.00 @ 90.95
AGGRESSIVE BUY 1860.00 @ 91.06
AGGRESSIVE SELL 900.00 @ 90.98
PASSIVE BUY 1980.00 @ 90.91
PASSIVE SELL 380.00 @ 91.12
PASSIVE BUY 980.00 @ 90.97
PASSIVE BUY 740.00 @ 91.03
PASSIVE SELL 460.00 @ 91.17
PASSIVE BUY 1180.00 @ 90.91
PASSIVE SELL 1940.00 @ 91.15
CANCEL SELL 1100.00 @ 91.18
PASSIVE SELL 2260.00 @ 91.21
CANCEL SELL 2260.00 @ 91.21
AGGRESSIVE SELL 2140.00 @ 91.01
CANCEL SELL 460.00 @ 91.17
PASSIVE BUY 2740.00 @ 90.99
PASSIVE BUY 1940.00 @ 90.94
CANCEL BUY 1980.00 @ 90.90
CANCEL BUY 100.00 @ 90.98
CANCEL BUY 2020.00 @ 90.95
CANCEL BUY -1980.00 @ 90.91
CANCEL BUY 980.00 @ 90.97
CANCEL BUY 1180.00 @ 90.91
CANCEL BUY 2740.00 @ 90.99
CANCEL BUY 1940.00 @ 90.94
PASSIVE SELL 2260.00 @ 91.00
CANCEL SELL 1940.00 @ 91.15
PASSIVE BUY 740.00 @ 90.98
PASSIVE SELL 1340.00 @ 91.08
CANCEL SELL -1060.00 @ 91.12
CANCEL SELL 380.00 @ 91.12
PASSIVE BUY 1060.00 @ 90.95
AGGRESSIVE SELL 2180.00 @ 90.84
CANCEL SELL 1580.00 @ 91.10
PASSIVE SELL 1260.00 @ 90.71
CANCEL SELL 1340.00 @ 91.08
AGGRESSIVE BUY 860.00 @ 90.71
PASSIVE SELL 900.00 @ 90.54
CANCEL SELL 740.00 @ 91.07
AGGRESSIVE BUY 1340.00 @ 90.81
AGGRESSIVE BUY 2220.00 @ 90.84
PASSIVE BUY 1260.00 @ 90.89
PASSIVE SELL 2060.00 @ 90.91
AGGRESSIVE SELL 1660.00 @ 90.85
PASSIVE SELL 1860.00 @ 90.98
PASSIVE BUY 1020.00 @ 90.80
PASSIVE BUY 1140.00 @ 90.82
PASSIVE SELL 2300.00 @ 90.98
PASSIVE SELL 1020.00 @ 90.89
CANCEL SELL -160.00 @ 91.06
CANCEL SELL 460.00 @ 91.06
PASSIVE SELL 1580.00 @ 90.89
AGGRESSIVE SELL 1220.00 @ 90.84
PASSIVE SELL 1980.00 @ 90.98
AGGRESSIVE BUY 740.00 @ 90.89
AGGRESSIVE SELL 540.00 @ 90.84
PASSIVE SELL 1100.00 @ 90.98
